FF

======================================================================

FAIL: test_distance1 (__main__.TestDistance)

----------------------------------------------------------------------

Traceback (most recent call last):

	File "c:\Users\Alex\GitHub\Customer-Distance-Test\TestDistance.py", line 9, in test_distance1
    
		self.assertEqual(41.77, distanceCalc.distance(testCoord))

AssertionError: 41.77 != 41.76872550078046


======================================================================

FAIL: test_distance2 (__main__.TestDistance)

----------------------------------------------------------------------

Traceback (most recent call last):
  
	File "c:\Users\Alex\GitHub\Customer-Distance-Test\TestDistance.py", line 14, in test_distance2
    
		self.assertEqual(309.94, distanceCalc.distance(testCoord1, testCoord2))
AssertionError: 309.94 != 309.9365659534358


----------------------------------------------------------------------
Ran 2 tests in 0.006s

FAILED (failures=2)